2025-05-20 13:26:46,532 INFO    Thread-15 :8044 [wandb_setup.py:_flush():70] Current SDK version is 0.19.11
2025-05-20 13:26:46,532 INFO    Thread-15 :8044 [wandb_setup.py:_flush():70] Configure stats pid to 8044
2025-05-20 13:26:46,532 INFO    Thread-15 :8044 [wandb_setup.py:_flush():70] Loading settings from C:\Users\DELL\.config\wandb\settings
2025-05-20 13:26:46,533 INFO    Thread-15 :8044 [wandb_setup.py:_flush():70] Loading settings from C:\Users\DELL\Documents\SEMESTER 8\Deep Learning\Assignment_3\DA6401-Assignment-3\wandb\settings
2025-05-20 13:26:46,533 INFO    Thread-15 :8044 [wandb_setup.py:_flush():70] Loading settings from environment variables
2025-05-20 13:26:46,533 INFO    Thread-15 :8044 [wandb_init.py:setup_run_log_directory():724] Logging user logs to C:\Users\DELL\Documents\SEMESTER 8\Deep Learning\Assignment_3\DA6401-Assignment-3\wandb\run-20250520_132646-a7yugoww\logs\debug.log
2025-05-20 13:26:46,534 INFO    Thread-15 :8044 [wandb_init.py:setup_run_log_directory():725] Logging internal logs to C:\Users\DELL\Documents\SEMESTER 8\Deep Learning\Assignment_3\DA6401-Assignment-3\wandb\run-20250520_132646-a7yugoww\logs\debug-internal.log
2025-05-20 13:26:46,534 INFO    Thread-15 :8044 [wandb_init.py:init():852] calling init triggers
2025-05-20 13:26:46,534 INFO    Thread-15 :8044 [wandb_init.py:init():857] wandb.init called with sweep_config: {'batch_size': 64, 'cell_type': 'lstm', 'clip': 1, 'data_dir': '.', 'dropout': 0.3, 'embedding_size': 64, 'hidden_size': 128, 'language': 'ta', 'learning_rate': 0.005056305687928137, 'max_seq_len': 50, 'momentum': 0.9, 'n_epochs': 20, 'num_layers': 5, 'optimizer': 'adam', 'rmsprop_alpha': 0.99, 'scheduler': 'plateau', 'scheduler_factor': 0.5, 'scheduler_patience': 5, 'scheduler_t_max': 20, 'teacher_forcing_ratio': 0.7, 'use_attention': False, 'weight_decay': 0}
config: {'_wandb': {}}
2025-05-20 13:26:46,534 INFO    Thread-15 :8044 [wandb_init.py:init():893] starting backend
2025-05-20 13:26:46,534 INFO    Thread-15 :8044 [wandb_init.py:init():897] sending inform_init request
2025-05-20 13:26:46,538 INFO    Thread-15 :8044 [backend.py:_multiprocessing_setup():101] multiprocessing start_methods=spawn, using: spawn
2025-05-20 13:26:46,538 INFO    Thread-15 :8044 [wandb_init.py:init():907] backend started and connected
2025-05-20 13:26:46,540 INFO    Thread-15 :8044 [wandb_run.py:_config_callback():1436] config_cb None None {'batch_size': 64, 'cell_type': 'lstm', 'clip': 1, 'data_dir': '.', 'dropout': 0.3, 'embedding_size': 64, 'hidden_size': 128, 'language': 'ta', 'learning_rate': 0.005056305687928137, 'max_seq_len': 50, 'momentum': 0.9, 'n_epochs': 20, 'num_layers': 5, 'optimizer': 'adam', 'rmsprop_alpha': 0.99, 'scheduler': 'plateau', 'scheduler_factor': 0.5, 'scheduler_patience': 5, 'scheduler_t_max': 20, 'teacher_forcing_ratio': 0.7, 'use_attention': False, 'weight_decay': 0}
2025-05-20 13:26:46,545 INFO    Thread-15 :8044 [wandb_init.py:init():1005] updated telemetry
2025-05-20 13:26:46,665 INFO    Thread-15 :8044 [wandb_init.py:init():1029] communicating run to backend with 90.0 second timeout
2025-05-20 13:26:47,499 INFO    Thread-15 :8044 [wandb_init.py:init():1104] starting run threads in backend
2025-05-20 13:26:48,145 INFO    Thread-15 :8044 [wandb_run.py:_console_start():2573] atexit reg
2025-05-20 13:26:48,145 INFO    Thread-15 :8044 [wandb_run.py:_redirect():2421] redirect: wrap_raw
2025-05-20 13:26:48,146 INFO    Thread-15 :8044 [wandb_run.py:_redirect():2490] Wrapping output streams.
2025-05-20 13:26:48,152 INFO    Thread-15 :8044 [wandb_run.py:_redirect():2513] Redirects installed.
2025-05-20 13:26:48,154 INFO    Thread-15 :8044 [wandb_init.py:init():1150] run started, returning control to user process
2025-05-20 14:48:15,686 INFO    Thread-8  :8044 [retry.py:__call__():175] [no run ID] Retry attempt failed:
Traceback (most recent call last):
  File "C:\Users\DELL\anaconda3\envs\Transliteration\lib\site-packages\urllib3\connection.py", line 198, in _new_conn
    sock = connection.create_connection(
  File "C:\Users\DELL\anaconda3\envs\Transliteration\lib\site-packages\urllib3\util\connection.py", line 60, in create_connection
    for res in socket.getaddrinfo(host, port, family, socket.SOCK_STREAM):
  File "C:\Users\DELL\anaconda3\envs\Transliteration\lib\socket.py", line 966, in getaddrinfo
    for res in _socket.getaddrinfo(host, port, family, type, proto, flags):
socket.gaierror: [Errno 11001] getaddrinfo failed

The above exception was the direct cause of the following exception:

Traceback (most recent call last):
  File "C:\Users\DELL\anaconda3\envs\Transliteration\lib\site-packages\urllib3\connectionpool.py", line 787, in urlopen
    response = self._make_request(
  File "C:\Users\DELL\anaconda3\envs\Transliteration\lib\site-packages\urllib3\connectionpool.py", line 488, in _make_request
    raise new_e
  File "C:\Users\DELL\anaconda3\envs\Transliteration\lib\site-packages\urllib3\connectionpool.py", line 464, in _make_request
    self._validate_conn(conn)
  File "C:\Users\DELL\anaconda3\envs\Transliteration\lib\site-packages\urllib3\connectionpool.py", line 1093, in _validate_conn
    conn.connect()
  File "C:\Users\DELL\anaconda3\envs\Transliteration\lib\site-packages\urllib3\connection.py", line 704, in connect
    self.sock = sock = self._new_conn()
  File "C:\Users\DELL\anaconda3\envs\Transliteration\lib\site-packages\urllib3\connection.py", line 205, in _new_conn
    raise NameResolutionError(self.host, self, e) from e
urllib3.exceptions.NameResolutionError: <urllib3.connection.HTTPSConnection object at 0x000001AD4FEE6BE0>: Failed to resolve 'api.wandb.ai' ([Errno 11001] getaddrinfo failed)

The above exception was the direct cause of the following exception:

Traceback (most recent call last):
  File "C:\Users\DELL\anaconda3\envs\Transliteration\lib\site-packages\requests\adapters.py", line 667, in send
    resp = conn.urlopen(
  File "C:\Users\DELL\anaconda3\envs\Transliteration\lib\site-packages\urllib3\connectionpool.py", line 841, in urlopen
    retries = retries.increment(
  File "C:\Users\DELL\anaconda3\envs\Transliteration\lib\site-packages\urllib3\util\retry.py", line 519, in increment
    raise MaxRetryError(_pool, url, reason) from reason  # type: ignore[arg-type]
urllib3.exceptions.MaxRetryError: HTTPSConnectionPool(host='api.wandb.ai', port=443): Max retries exceeded with url: /graphql (Caused by NameResolutionError("<urllib3.connection.HTTPSConnection object at 0x000001AD4FEE6BE0>: Failed to resolve 'api.wandb.ai' ([Errno 11001] getaddrinfo failed)"))

During handling of the above exception, another exception occurred:

Traceback (most recent call last):
  File "C:\Users\DELL\anaconda3\envs\Transliteration\lib\site-packages\wandb\sdk\lib\retry.py", line 134, in __call__
    result = self._call_fn(*args, **kwargs)
  File "C:\Users\DELL\anaconda3\envs\Transliteration\lib\site-packages\wandb\sdk\internal\internal_api.py", line 398, in execute
    return self.client.execute(*args, **kwargs)  # type: ignore
  File "C:\Users\DELL\anaconda3\envs\Transliteration\lib\site-packages\wandb\vendor\gql-0.2.0\wandb_gql\client.py", line 52, in execute
    result = self._get_result(document, *args, **kwargs)
  File "C:\Users\DELL\anaconda3\envs\Transliteration\lib\site-packages\wandb\vendor\gql-0.2.0\wandb_gql\client.py", line 60, in _get_result
    return self.transport.execute(document, *args, **kwargs)
  File "C:\Users\DELL\anaconda3\envs\Transliteration\lib\site-packages\wandb\sdk\lib\gql_request.py", line 58, in execute
    request = self.session.post(self.url, **post_args)
  File "C:\Users\DELL\anaconda3\envs\Transliteration\lib\site-packages\requests\sessions.py", line 637, in post
    return self.request("POST", url, data=data, json=json, **kwargs)
  File "C:\Users\DELL\anaconda3\envs\Transliteration\lib\site-packages\requests\sessions.py", line 589, in request
    resp = self.send(prep, **send_kwargs)
  File "C:\Users\DELL\anaconda3\envs\Transliteration\lib\site-packages\requests\sessions.py", line 703, in send
    r = adapter.send(request, **kwargs)
  File "C:\Users\DELL\anaconda3\envs\Transliteration\lib\site-packages\requests\adapters.py", line 700, in send
    raise ConnectionError(e, request=request)
requests.exceptions.ConnectionError: HTTPSConnectionPool(host='api.wandb.ai', port=443): Max retries exceeded with url: /graphql (Caused by NameResolutionError("<urllib3.connection.HTTPSConnection object at 0x000001AD4FEE6BE0>: Failed to resolve 'api.wandb.ai' ([Errno 11001] getaddrinfo failed)"))
2025-05-20 18:07:48,906 INFO    Thread-15 :8044 [wandb_run.py:_finish():2321] finishing run teja_sai-indian-institute-of-technology-madras/transliteration-seq2seq/a7yugoww
2025-05-20 18:07:48,908 INFO    Thread-15 :8044 [wandb_run.py:_atexit_cleanup():2538] got exitcode: 0
2025-05-20 18:07:48,909 INFO    Thread-15 :8044 [wandb_run.py:_restore():2520] restore
2025-05-20 18:07:48,909 INFO    Thread-15 :8044 [wandb_run.py:_restore():2526] restore done
2025-05-20 18:07:50,988 INFO    Thread-15 :8044 [wandb_run.py:_footer_history_summary_info():4188] rendering history
2025-05-20 18:07:50,989 INFO    Thread-15 :8044 [wandb_run.py:_footer_history_summary_info():4220] rendering summary
2025-05-20 18:07:50,990 INFO    Thread-15 :8044 [wandb_run.py:_footer_sync_info():4149] logging synced files
